[2023-10-11T10:00:01.812+0000] {warnings.py:109} WARNING - /home/airflow/.local/lib/python3.8/site-packages/airflow/utils/sqlalchemy.py:124: DeprecationWarning: The sql_alchemy_conn option in [core] has been moved to the sql_alchemy_conn option in [database] - the old setting has been used, but please update your config.
  return not conf.get("database", "sql_alchemy_conn").startswith("mssql")

[2023-10-11T10:00:01.919+0000] {taskinstance.py:1159} INFO - Dependencies all met for dep_context=non-requeueable deps ti=<TaskInstance: ETL.crawl_data scheduled__2023-10-11T09:00:00+00:00 [queued]>
[2023-10-11T10:00:01.924+0000] {taskinstance.py:1159} INFO - Dependencies all met for dep_context=requeueable deps ti=<TaskInstance: ETL.crawl_data scheduled__2023-10-11T09:00:00+00:00 [queued]>
[2023-10-11T10:00:01.924+0000] {taskinstance.py:1361} INFO - Starting attempt 1 of 1
[2023-10-11T10:00:01.931+0000] {taskinstance.py:1382} INFO - Executing <Task(PythonOperator): crawl_data> on 2023-10-11 09:00:00+00:00
[2023-10-11T10:00:01.934+0000] {standard_task_runner.py:57} INFO - Started process 296 to run task
[2023-10-11T10:00:01.936+0000] {standard_task_runner.py:84} INFO - Running: ['airflow', 'tasks', 'run', 'ETL', 'crawl_data', 'scheduled__2023-10-11T09:00:00+00:00', '--job-id', '571', '--raw', '--subdir', 'DAGS_FOLDER/pipeline.py', '--cfg-path', '/tmp/tmpzocyjqu_']
[2023-10-11T10:00:01.937+0000] {standard_task_runner.py:85} INFO - Job 571: Subtask crawl_data
[2023-10-11T10:00:01.945+0000] {warnings.py:109} WARNING - /home/airflow/.local/lib/python3.8/site-packages/airflow/settings.py:195: DeprecationWarning: The sql_alchemy_conn option in [core] has been moved to the sql_alchemy_conn option in [database] - the old setting has been used, but please update your config.
  SQL_ALCHEMY_CONN = conf.get("database", "SQL_ALCHEMY_CONN")

[2023-10-11T10:00:01.967+0000] {task_command.py:415} INFO - Running <TaskInstance: ETL.crawl_data scheduled__2023-10-11T09:00:00+00:00 [running]> on host cba2d0d235e2
[2023-10-11T10:00:01.973+0000] {warnings.py:109} WARNING - /home/airflow/.local/lib/python3.8/site-packages/airflow/utils/sqlalchemy.py:124: DeprecationWarning: The sql_alchemy_conn option in [core] has been moved to the sql_alchemy_conn option in [database] - the old setting has been used, but please update your config.
  return not conf.get("database", "sql_alchemy_conn").startswith("mssql")

[2023-10-11T10:00:02.026+0000] {taskinstance.py:1660} INFO - Exporting env vars: AIRFLOW_CTX_DAG_OWNER='airflow' AIRFLOW_CTX_DAG_ID='ETL' AIRFLOW_CTX_TASK_ID='crawl_data' AIRFLOW_CTX_EXECUTION_DATE='2023-10-11T09:00:00+00:00' AIRFLOW_CTX_TRY_NUMBER='1' AIRFLOW_CTX_DAG_RUN_ID='scheduled__2023-10-11T09:00:00+00:00'
[2023-10-11T10:00:02.032+0000] {base.py:73} INFO - Using connection ID 'Booking' for task execution.
[2023-10-11T10:00:02.340+0000] {logging_mixin.py:151} INFO - checkin, checkout, weekday 2023-12-20 2023-12-21 Wednesday
[2023-10-11T10:00:02.341+0000] {logging_mixin.py:151} INFO - link https://www.booking.com/searchresults.vi.html?ss=TP.+H%C3%B4%CC%80+Chi%CC%81+Minh%2C+Vi%C3%AA%CC%A3t+Nam&efdco=1&label=gen173nr-1BCAEoggI46AdIM1gEaPQBiAEBmAEquAEXyAEM2AEB6AEBiAIBqAIDuAL1lMaoBsACAdICJGM1MWM1ODQyLWYzMmMtNGExMi1iMWFmLWM4YzliMDE0MzJlMNgCBeACAQ&sid=a3cf4761bc87283185953cebac7c42a2&aid=304142&lang=vi&sb=1&src_elem=sb&src=index&dest_id=-3730078&dest_type=city&checkin=2023-12-20&checkout=2023-12-21&group_adults=2&no_rooms=1&group_children=0&sb_travel_purpose=leisure&selected_currency=VND&offset={}
[2023-10-11T10:00:10.359+0000] {taskinstance.py:1943} ERROR - Task failed with exception
Traceback (most recent call last):
  File "/home/airflow/.local/lib/python3.8/site-packages/urllib3/connection.py", line 174, in _new_conn
    conn = connection.create_connection(
  File "/home/airflow/.local/lib/python3.8/site-packages/urllib3/util/connection.py", line 72, in create_connection
    for res in socket.getaddrinfo(host, port, family, socket.SOCK_STREAM):
  File "/usr/local/lib/python3.8/socket.py", line 918, in getaddrinfo
    for res in _socket.getaddrinfo(host, port, family, type, proto, flags):
socket.gaierror: [Errno -3] Temporary failure in name resolution

During handling of the above exception, another exception occurred:

Traceback (most recent call last):
  File "/home/airflow/.local/lib/python3.8/site-packages/urllib3/connectionpool.py", line 714, in urlopen
    httplib_response = self._make_request(
  File "/home/airflow/.local/lib/python3.8/site-packages/urllib3/connectionpool.py", line 403, in _make_request
    self._validate_conn(conn)
  File "/home/airflow/.local/lib/python3.8/site-packages/urllib3/connectionpool.py", line 1053, in _validate_conn
    conn.connect()
  File "/home/airflow/.local/lib/python3.8/site-packages/urllib3/connection.py", line 363, in connect
    self.sock = conn = self._new_conn()
  File "/home/airflow/.local/lib/python3.8/site-packages/urllib3/connection.py", line 186, in _new_conn
    raise NewConnectionError(
urllib3.exceptions.NewConnectionError: <urllib3.connection.HTTPSConnection object at 0xffff8e793700>: Failed to establish a new connection: [Errno -3] Temporary failure in name resolution

During handling of the above exception, another exception occurred:

Traceback (most recent call last):
  File "/home/airflow/.local/lib/python3.8/site-packages/requests/adapters.py", line 486, in send
    resp = conn.urlopen(
  File "/home/airflow/.local/lib/python3.8/site-packages/urllib3/connectionpool.py", line 798, in urlopen
    retries = retries.increment(
  File "/home/airflow/.local/lib/python3.8/site-packages/urllib3/util/retry.py", line 592, in increment
    raise MaxRetryError(_pool, url, error or ResponseError(cause))
urllib3.exceptions.MaxRetryError: HTTPSConnectionPool(host='www.booking.com', port=443): Max retries exceeded with url: /searchresults.vi.html?ss=TP.+H%C3%B4%CC%80+Chi%CC%81+Minh%2C+Vi%C3%AA%CC%A3t+Nam&efdco=1&label=gen173nr-1BCAEoggI46AdIM1gEaPQBiAEBmAEquAEXyAEM2AEB6AEBiAIBqAIDuAL1lMaoBsACAdICJGM1MWM1ODQyLWYzMmMtNGExMi1iMWFmLWM4YzliMDE0MzJlMNgCBeACAQ&sid=a3cf4761bc87283185953cebac7c42a2&aid=304142&lang=vi&sb=1&src_elem=sb&src=index&dest_id=-3730078&dest_type=city&checkin=2023-12-20&checkout=2023-12-21&group_adults=2&no_rooms=1&group_children=0&sb_travel_purpose=leisure&selected_currency=VND&offset=0 (Caused by NewConnectionError('<urllib3.connection.HTTPSConnection object at 0xffff8e793700>: Failed to establish a new connection: [Errno -3] Temporary failure in name resolution'))

During handling of the above exception, another exception occurred:

Traceback (most recent call last):
  File "/home/airflow/.local/lib/python3.8/site-packages/airflow/operators/python.py", line 192, in execute
    return_value = self.execute_callable()
  File "/home/airflow/.local/lib/python3.8/site-packages/airflow/operators/python.py", line 209, in execute_callable
    return self.python_callable(*self.op_args, **self.op_kwargs)
  File "/opt/airflow/dags/help_function/ETL_Data.py", line 25, in extract_data
    data = get_today_dataframe(checkin, checkout, weekday,booking_links)
  File "/opt/airflow/dags/help_function/crawl_func.py", line 177, in get_today_dataframe
    df = crawl_booking_data(link, checkin, checkout, adult, room, children, currency)
  File "/opt/airflow/dags/help_function/crawl_func.py", line 103, in crawl_booking_data
    response = requests.get(url, headers=headers)
  File "/home/airflow/.local/lib/python3.8/site-packages/requests/api.py", line 73, in get
    return request("get", url, params=params, **kwargs)
  File "/home/airflow/.local/lib/python3.8/site-packages/requests/api.py", line 59, in request
    return session.request(method=method, url=url, **kwargs)
  File "/home/airflow/.local/lib/python3.8/site-packages/requests/sessions.py", line 589, in request
    resp = self.send(prep, **send_kwargs)
  File "/home/airflow/.local/lib/python3.8/site-packages/requests/sessions.py", line 703, in send
    r = adapter.send(request, **kwargs)
  File "/home/airflow/.local/lib/python3.8/site-packages/requests/adapters.py", line 519, in send
    raise ConnectionError(e, request=request)
requests.exceptions.ConnectionError: HTTPSConnectionPool(host='www.booking.com', port=443): Max retries exceeded with url: /searchresults.vi.html?ss=TP.+H%C3%B4%CC%80+Chi%CC%81+Minh%2C+Vi%C3%AA%CC%A3t+Nam&efdco=1&label=gen173nr-1BCAEoggI46AdIM1gEaPQBiAEBmAEquAEXyAEM2AEB6AEBiAIBqAIDuAL1lMaoBsACAdICJGM1MWM1ODQyLWYzMmMtNGExMi1iMWFmLWM4YzliMDE0MzJlMNgCBeACAQ&sid=a3cf4761bc87283185953cebac7c42a2&aid=304142&lang=vi&sb=1&src_elem=sb&src=index&dest_id=-3730078&dest_type=city&checkin=2023-12-20&checkout=2023-12-21&group_adults=2&no_rooms=1&group_children=0&sb_travel_purpose=leisure&selected_currency=VND&offset=0 (Caused by NewConnectionError('<urllib3.connection.HTTPSConnection object at 0xffff8e793700>: Failed to establish a new connection: [Errno -3] Temporary failure in name resolution'))
[2023-10-11T10:00:10.386+0000] {taskinstance.py:1400} INFO - Marking task as FAILED. dag_id=ETL, task_id=crawl_data, execution_date=20231011T090000, start_date=20231011T100001, end_date=20231011T100010
[2023-10-11T10:00:10.400+0000] {standard_task_runner.py:104} ERROR - Failed to execute job 571 for task crawl_data (HTTPSConnectionPool(host='www.booking.com', port=443): Max retries exceeded with url: /searchresults.vi.html?ss=TP.+H%C3%B4%CC%80+Chi%CC%81+Minh%2C+Vi%C3%AA%CC%A3t+Nam&efdco=1&label=gen173nr-1BCAEoggI46AdIM1gEaPQBiAEBmAEquAEXyAEM2AEB6AEBiAIBqAIDuAL1lMaoBsACAdICJGM1MWM1ODQyLWYzMmMtNGExMi1iMWFmLWM4YzliMDE0MzJlMNgCBeACAQ&sid=a3cf4761bc87283185953cebac7c42a2&aid=304142&lang=vi&sb=1&src_elem=sb&src=index&dest_id=-3730078&dest_type=city&checkin=2023-12-20&checkout=2023-12-21&group_adults=2&no_rooms=1&group_children=0&sb_travel_purpose=leisure&selected_currency=VND&offset=0 (Caused by NewConnectionError('<urllib3.connection.HTTPSConnection object at 0xffff8e793700>: Failed to establish a new connection: [Errno -3] Temporary failure in name resolution')); 296)
[2023-10-11T10:00:10.420+0000] {local_task_job_runner.py:228} INFO - Task exited with return code 1
[2023-10-11T10:00:10.437+0000] {taskinstance.py:2784} INFO - 0 downstream tasks scheduled from follow-on schedule check
